[07/07/2018 11:37] ERROR red <module> 634: Fatal exception, attempting graceful logout
Traceback (most recent call last):
  File "/Library/Frameworks/Python.framework/Versions/3.6/lib/python3.6/site-packages/aiohttp/connector.py", line 601, in _create_direct_connection
    local_addr=self._local_addr)
  File "/Library/Frameworks/Python.framework/Versions/3.6/lib/python3.6/asyncio/base_events.py", line 803, in create_connection
    sock, protocol_factory, ssl, server_hostname)
  File "/Library/Frameworks/Python.framework/Versions/3.6/lib/python3.6/asyncio/base_events.py", line 829, in _create_connection_transport
    yield from waiter
  File "/Library/Frameworks/Python.framework/Versions/3.6/lib/python3.6/asyncio/sslproto.py", line 501, in data_received
    ssldata, appdata = self._sslpipe.feed_ssldata(data)
  File "/Library/Frameworks/Python.framework/Versions/3.6/lib/python3.6/asyncio/sslproto.py", line 201, in feed_ssldata
    self._sslobj.do_handshake()
  File "/Library/Frameworks/Python.framework/Versions/3.6/lib/python3.6/ssl.py", line 689, in do_handshake
    self._sslobj.do_handshake()
ssl.SSLError: [SSL: CERTIFICATE_VERIFY_FAILED] certificate verify failed (_ssl.c:777)

The above exception was the direct cause of the following exception:

Traceback (most recent call last):
  File "/Library/Frameworks/Python.framework/Versions/3.6/lib/python3.6/site-packages/aiohttp/connector.py", line 304, in connect
    yield from self._create_connection(req)
  File "/Library/Frameworks/Python.framework/Versions/3.6/lib/python3.6/site-packages/aiohttp/connector.py", line 578, in _create_connection
    transport, proto = yield from self._create_direct_connection(req)
  File "/Library/Frameworks/Python.framework/Versions/3.6/lib/python3.6/site-packages/aiohttp/connector.py", line 624, in _create_direct_connection
    (req.host, req.port, exc.strerror)) from exc
aiohttp.errors.ClientOSError: [Errno 1] Can not connect to discordapp.com:443 [[SSL: CERTIFICATE_VERIFY_FAILED] certificate verify failed (_ssl.c:777)]

The above exception was the direct cause of the following exception:

Traceback (most recent call last):
  File "red.py", line 614, in <module>
    loop.run_until_complete(main(bot))
  File "/Library/Frameworks/Python.framework/Versions/3.6/lib/python3.6/asyncio/base_events.py", line 467, in run_until_complete
    return future.result()
  File "red.py", line 599, in main
    bot=not bot.settings.self_bot)
  File "/Library/Frameworks/Python.framework/Versions/3.6/lib/python3.6/site-packages/discord/client.py", line 416, in login
    yield from getattr(self, '_login_' + str(n))(*args, **kwargs)
  File "/Library/Frameworks/Python.framework/Versions/3.6/lib/python3.6/site-packages/discord/client.py", line 346, in _login_1
    data = yield from self.http.static_login(token, bot=is_bot)
  File "/Library/Frameworks/Python.framework/Versions/3.6/lib/python3.6/site-packages/discord/http.py", line 258, in static_login
    data = yield from self.request(Route('GET', '/users/@me'))
  File "/Library/Frameworks/Python.framework/Versions/3.6/lib/python3.6/site-packages/discord/http.py", line 137, in request
    r = yield from self.session.request(method, url, **kwargs)
  File "/Library/Frameworks/Python.framework/Versions/3.6/lib/python3.6/site-packages/aiohttp/client.py", line 555, in __iter__
    resp = yield from self._coro
  File "/Library/Frameworks/Python.framework/Versions/3.6/lib/python3.6/site-packages/aiohttp/client.py", line 198, in _request
    conn = yield from self._connector.connect(req)
  File "/Library/Frameworks/Python.framework/Versions/3.6/lib/python3.6/site-packages/aiohttp/connector.py", line 314, in connect
    .format(key, exc.strerror)) from exc
aiohttp.errors.ClientOSError: [Errno 1] Cannot connect to host discordapp.com:443 ssl:True [Can not connect to discordapp.com:443 [[SSL: CERTIFICATE_VERIFY_FAILED] certificate verify failed (_ssl.c:777)]]
[07/07/2018 11:38] ERROR red <module> 634: Fatal exception, attempting graceful logout
Traceback (most recent call last):
  File "/Library/Frameworks/Python.framework/Versions/3.6/lib/python3.6/site-packages/aiohttp/connector.py", line 601, in _create_direct_connection
    local_addr=self._local_addr)
  File "/Library/Frameworks/Python.framework/Versions/3.6/lib/python3.6/asyncio/base_events.py", line 803, in create_connection
    sock, protocol_factory, ssl, server_hostname)
  File "/Library/Frameworks/Python.framework/Versions/3.6/lib/python3.6/asyncio/base_events.py", line 829, in _create_connection_transport
    yield from waiter
  File "/Library/Frameworks/Python.framework/Versions/3.6/lib/python3.6/asyncio/sslproto.py", line 501, in data_received
    ssldata, appdata = self._sslpipe.feed_ssldata(data)
  File "/Library/Frameworks/Python.framework/Versions/3.6/lib/python3.6/asyncio/sslproto.py", line 201, in feed_ssldata
    self._sslobj.do_handshake()
  File "/Library/Frameworks/Python.framework/Versions/3.6/lib/python3.6/ssl.py", line 689, in do_handshake
    self._sslobj.do_handshake()
ssl.SSLError: [SSL: CERTIFICATE_VERIFY_FAILED] certificate verify failed (_ssl.c:777)

The above exception was the direct cause of the following exception:

Traceback (most recent call last):
  File "/Library/Frameworks/Python.framework/Versions/3.6/lib/python3.6/site-packages/aiohttp/connector.py", line 304, in connect
    yield from self._create_connection(req)
  File "/Library/Frameworks/Python.framework/Versions/3.6/lib/python3.6/site-packages/aiohttp/connector.py", line 578, in _create_connection
    transport, proto = yield from self._create_direct_connection(req)
  File "/Library/Frameworks/Python.framework/Versions/3.6/lib/python3.6/site-packages/aiohttp/connector.py", line 624, in _create_direct_connection
    (req.host, req.port, exc.strerror)) from exc
aiohttp.errors.ClientOSError: [Errno 1] Can not connect to discordapp.com:443 [[SSL: CERTIFICATE_VERIFY_FAILED] certificate verify failed (_ssl.c:777)]

The above exception was the direct cause of the following exception:

Traceback (most recent call last):
  File "red.py", line 614, in <module>
    loop.run_until_complete(main(bot))
  File "/Library/Frameworks/Python.framework/Versions/3.6/lib/python3.6/asyncio/base_events.py", line 467, in run_until_complete
    return future.result()
  File "red.py", line 599, in main
    bot=not bot.settings.self_bot)
  File "/Library/Frameworks/Python.framework/Versions/3.6/lib/python3.6/site-packages/discord/client.py", line 416, in login
    yield from getattr(self, '_login_' + str(n))(*args, **kwargs)
  File "/Library/Frameworks/Python.framework/Versions/3.6/lib/python3.6/site-packages/discord/client.py", line 346, in _login_1
    data = yield from self.http.static_login(token, bot=is_bot)
  File "/Library/Frameworks/Python.framework/Versions/3.6/lib/python3.6/site-packages/discord/http.py", line 258, in static_login
    data = yield from self.request(Route('GET', '/users/@me'))
  File "/Library/Frameworks/Python.framework/Versions/3.6/lib/python3.6/site-packages/discord/http.py", line 137, in request
    r = yield from self.session.request(method, url, **kwargs)
  File "/Library/Frameworks/Python.framework/Versions/3.6/lib/python3.6/site-packages/aiohttp/client.py", line 555, in __iter__
    resp = yield from self._coro
  File "/Library/Frameworks/Python.framework/Versions/3.6/lib/python3.6/site-packages/aiohttp/client.py", line 198, in _request
    conn = yield from self._connector.connect(req)
  File "/Library/Frameworks/Python.framework/Versions/3.6/lib/python3.6/site-packages/aiohttp/connector.py", line 314, in connect
    .format(key, exc.strerror)) from exc
aiohttp.errors.ClientOSError: [Errno 1] Cannot connect to host discordapp.com:443 ssl:True [Can not connect to discordapp.com:443 [[SSL: CERTIFICATE_VERIFY_FAILED] certificate verify failed (_ssl.c:777)]]
[07/07/2018 11:38] ERROR red <module> 634: Fatal exception, attempting graceful logout
Traceback (most recent call last):
  File "/Library/Frameworks/Python.framework/Versions/3.6/lib/python3.6/site-packages/aiohttp/connector.py", line 601, in _create_direct_connection
    local_addr=self._local_addr)
  File "/Library/Frameworks/Python.framework/Versions/3.6/lib/python3.6/asyncio/base_events.py", line 803, in create_connection
    sock, protocol_factory, ssl, server_hostname)
  File "/Library/Frameworks/Python.framework/Versions/3.6/lib/python3.6/asyncio/base_events.py", line 829, in _create_connection_transport
    yield from waiter
  File "/Library/Frameworks/Python.framework/Versions/3.6/lib/python3.6/asyncio/sslproto.py", line 501, in data_received
    ssldata, appdata = self._sslpipe.feed_ssldata(data)
  File "/Library/Frameworks/Python.framework/Versions/3.6/lib/python3.6/asyncio/sslproto.py", line 201, in feed_ssldata
    self._sslobj.do_handshake()
  File "/Library/Frameworks/Python.framework/Versions/3.6/lib/python3.6/ssl.py", line 689, in do_handshake
    self._sslobj.do_handshake()
ssl.SSLError: [SSL: CERTIFICATE_VERIFY_FAILED] certificate verify failed (_ssl.c:777)

The above exception was the direct cause of the following exception:

Traceback (most recent call last):
  File "/Library/Frameworks/Python.framework/Versions/3.6/lib/python3.6/site-packages/aiohttp/connector.py", line 304, in connect
    yield from self._create_connection(req)
  File "/Library/Frameworks/Python.framework/Versions/3.6/lib/python3.6/site-packages/aiohttp/connector.py", line 578, in _create_connection
    transport, proto = yield from self._create_direct_connection(req)
  File "/Library/Frameworks/Python.framework/Versions/3.6/lib/python3.6/site-packages/aiohttp/connector.py", line 624, in _create_direct_connection
    (req.host, req.port, exc.strerror)) from exc
aiohttp.errors.ClientOSError: [Errno 1] Can not connect to discordapp.com:443 [[SSL: CERTIFICATE_VERIFY_FAILED] certificate verify failed (_ssl.c:777)]

The above exception was the direct cause of the following exception:

Traceback (most recent call last):
  File "red.py", line 614, in <module>
    loop.run_until_complete(main(bot))
  File "/Library/Frameworks/Python.framework/Versions/3.6/lib/python3.6/asyncio/base_events.py", line 467, in run_until_complete
    return future.result()
  File "red.py", line 599, in main
    bot=not bot.settings.self_bot)
  File "/Library/Frameworks/Python.framework/Versions/3.6/lib/python3.6/site-packages/discord/client.py", line 416, in login
    yield from getattr(self, '_login_' + str(n))(*args, **kwargs)
  File "/Library/Frameworks/Python.framework/Versions/3.6/lib/python3.6/site-packages/discord/client.py", line 346, in _login_1
    data = yield from self.http.static_login(token, bot=is_bot)
  File "/Library/Frameworks/Python.framework/Versions/3.6/lib/python3.6/site-packages/discord/http.py", line 258, in static_login
    data = yield from self.request(Route('GET', '/users/@me'))
  File "/Library/Frameworks/Python.framework/Versions/3.6/lib/python3.6/site-packages/discord/http.py", line 137, in request
    r = yield from self.session.request(method, url, **kwargs)
  File "/Library/Frameworks/Python.framework/Versions/3.6/lib/python3.6/site-packages/aiohttp/client.py", line 555, in __iter__
    resp = yield from self._coro
  File "/Library/Frameworks/Python.framework/Versions/3.6/lib/python3.6/site-packages/aiohttp/client.py", line 198, in _request
    conn = yield from self._connector.connect(req)
  File "/Library/Frameworks/Python.framework/Versions/3.6/lib/python3.6/site-packages/aiohttp/connector.py", line 314, in connect
    .format(key, exc.strerror)) from exc
aiohttp.errors.ClientOSError: [Errno 1] Cannot connect to host discordapp.com:443 ssl:True [Can not connect to discordapp.com:443 [[SSL: CERTIFICATE_VERIFY_FAILED] certificate verify failed (_ssl.c:777)]]
[07/07/2018 11:38] ERROR red <module> 634: Fatal exception, attempting graceful logout
Traceback (most recent call last):
  File "/Library/Frameworks/Python.framework/Versions/3.6/lib/python3.6/site-packages/aiohttp/connector.py", line 601, in _create_direct_connection
    local_addr=self._local_addr)
  File "/Library/Frameworks/Python.framework/Versions/3.6/lib/python3.6/asyncio/base_events.py", line 803, in create_connection
    sock, protocol_factory, ssl, server_hostname)
  File "/Library/Frameworks/Python.framework/Versions/3.6/lib/python3.6/asyncio/base_events.py", line 829, in _create_connection_transport
    yield from waiter
  File "/Library/Frameworks/Python.framework/Versions/3.6/lib/python3.6/asyncio/sslproto.py", line 501, in data_received
    ssldata, appdata = self._sslpipe.feed_ssldata(data)
  File "/Library/Frameworks/Python.framework/Versions/3.6/lib/python3.6/asyncio/sslproto.py", line 201, in feed_ssldata
    self._sslobj.do_handshake()
  File "/Library/Frameworks/Python.framework/Versions/3.6/lib/python3.6/ssl.py", line 689, in do_handshake
    self._sslobj.do_handshake()
ssl.SSLError: [SSL: CERTIFICATE_VERIFY_FAILED] certificate verify failed (_ssl.c:777)

The above exception was the direct cause of the following exception:

Traceback (most recent call last):
  File "/Library/Frameworks/Python.framework/Versions/3.6/lib/python3.6/site-packages/aiohttp/connector.py", line 304, in connect
    yield from self._create_connection(req)
  File "/Library/Frameworks/Python.framework/Versions/3.6/lib/python3.6/site-packages/aiohttp/connector.py", line 578, in _create_connection
    transport, proto = yield from self._create_direct_connection(req)
  File "/Library/Frameworks/Python.framework/Versions/3.6/lib/python3.6/site-packages/aiohttp/connector.py", line 624, in _create_direct_connection
    (req.host, req.port, exc.strerror)) from exc
aiohttp.errors.ClientOSError: [Errno 1] Can not connect to discordapp.com:443 [[SSL: CERTIFICATE_VERIFY_FAILED] certificate verify failed (_ssl.c:777)]

The above exception was the direct cause of the following exception:

Traceback (most recent call last):
  File "red.py", line 614, in <module>
    loop.run_until_complete(main(bot))
  File "/Library/Frameworks/Python.framework/Versions/3.6/lib/python3.6/asyncio/base_events.py", line 467, in run_until_complete
    return future.result()
  File "red.py", line 599, in main
    bot=not bot.settings.self_bot)
  File "/Library/Frameworks/Python.framework/Versions/3.6/lib/python3.6/site-packages/discord/client.py", line 416, in login
    yield from getattr(self, '_login_' + str(n))(*args, **kwargs)
  File "/Library/Frameworks/Python.framework/Versions/3.6/lib/python3.6/site-packages/discord/client.py", line 346, in _login_1
    data = yield from self.http.static_login(token, bot=is_bot)
  File "/Library/Frameworks/Python.framework/Versions/3.6/lib/python3.6/site-packages/discord/http.py", line 258, in static_login
    data = yield from self.request(Route('GET', '/users/@me'))
  File "/Library/Frameworks/Python.framework/Versions/3.6/lib/python3.6/site-packages/discord/http.py", line 137, in request
    r = yield from self.session.request(method, url, **kwargs)
  File "/Library/Frameworks/Python.framework/Versions/3.6/lib/python3.6/site-packages/aiohttp/client.py", line 555, in __iter__
    resp = yield from self._coro
  File "/Library/Frameworks/Python.framework/Versions/3.6/lib/python3.6/site-packages/aiohttp/client.py", line 198, in _request
    conn = yield from self._connector.connect(req)
  File "/Library/Frameworks/Python.framework/Versions/3.6/lib/python3.6/site-packages/aiohttp/connector.py", line 314, in connect
    .format(key, exc.strerror)) from exc
aiohttp.errors.ClientOSError: [Errno 1] Cannot connect to host discordapp.com:443 ssl:True [Can not connect to discordapp.com:443 [[SSL: CERTIFICATE_VERIFY_FAILED] certificate verify failed (_ssl.c:777)]]
[07/07/2018 11:38] ERROR red <module> 634: Fatal exception, attempting graceful logout
Traceback (most recent call last):
  File "/Library/Frameworks/Python.framework/Versions/3.6/lib/python3.6/site-packages/aiohttp/connector.py", line 601, in _create_direct_connection
    local_addr=self._local_addr)
  File "/Library/Frameworks/Python.framework/Versions/3.6/lib/python3.6/asyncio/base_events.py", line 803, in create_connection
    sock, protocol_factory, ssl, server_hostname)
  File "/Library/Frameworks/Python.framework/Versions/3.6/lib/python3.6/asyncio/base_events.py", line 829, in _create_connection_transport
    yield from waiter
  File "/Library/Frameworks/Python.framework/Versions/3.6/lib/python3.6/asyncio/sslproto.py", line 501, in data_received
    ssldata, appdata = self._sslpipe.feed_ssldata(data)
  File "/Library/Frameworks/Python.framework/Versions/3.6/lib/python3.6/asyncio/sslproto.py", line 201, in feed_ssldata
    self._sslobj.do_handshake()
  File "/Library/Frameworks/Python.framework/Versions/3.6/lib/python3.6/ssl.py", line 689, in do_handshake
    self._sslobj.do_handshake()
ssl.SSLError: [SSL: CERTIFICATE_VERIFY_FAILED] certificate verify failed (_ssl.c:777)

The above exception was the direct cause of the following exception:

Traceback (most recent call last):
  File "/Library/Frameworks/Python.framework/Versions/3.6/lib/python3.6/site-packages/aiohttp/connector.py", line 304, in connect
    yield from self._create_connection(req)
  File "/Library/Frameworks/Python.framework/Versions/3.6/lib/python3.6/site-packages/aiohttp/connector.py", line 578, in _create_connection
    transport, proto = yield from self._create_direct_connection(req)
  File "/Library/Frameworks/Python.framework/Versions/3.6/lib/python3.6/site-packages/aiohttp/connector.py", line 624, in _create_direct_connection
    (req.host, req.port, exc.strerror)) from exc
aiohttp.errors.ClientOSError: [Errno 1] Can not connect to discordapp.com:443 [[SSL: CERTIFICATE_VERIFY_FAILED] certificate verify failed (_ssl.c:777)]

The above exception was the direct cause of the following exception:

Traceback (most recent call last):
  File "red.py", line 614, in <module>
    loop.run_until_complete(main(bot))
  File "/Library/Frameworks/Python.framework/Versions/3.6/lib/python3.6/asyncio/base_events.py", line 467, in run_until_complete
    return future.result()
  File "red.py", line 599, in main
    bot=not bot.settings.self_bot)
  File "/Library/Frameworks/Python.framework/Versions/3.6/lib/python3.6/site-packages/discord/client.py", line 416, in login
    yield from getattr(self, '_login_' + str(n))(*args, **kwargs)
  File "/Library/Frameworks/Python.framework/Versions/3.6/lib/python3.6/site-packages/discord/client.py", line 346, in _login_1
    data = yield from self.http.static_login(token, bot=is_bot)
  File "/Library/Frameworks/Python.framework/Versions/3.6/lib/python3.6/site-packages/discord/http.py", line 258, in static_login
    data = yield from self.request(Route('GET', '/users/@me'))
  File "/Library/Frameworks/Python.framework/Versions/3.6/lib/python3.6/site-packages/discord/http.py", line 137, in request
    r = yield from self.session.request(method, url, **kwargs)
  File "/Library/Frameworks/Python.framework/Versions/3.6/lib/python3.6/site-packages/aiohttp/client.py", line 555, in __iter__
    resp = yield from self._coro
  File "/Library/Frameworks/Python.framework/Versions/3.6/lib/python3.6/site-packages/aiohttp/client.py", line 198, in _request
    conn = yield from self._connector.connect(req)
  File "/Library/Frameworks/Python.framework/Versions/3.6/lib/python3.6/site-packages/aiohttp/connector.py", line 314, in connect
    .format(key, exc.strerror)) from exc
aiohttp.errors.ClientOSError: [Errno 1] Cannot connect to host discordapp.com:443 ssl:True [Can not connect to discordapp.com:443 [[SSL: CERTIFICATE_VERIFY_FAILED] certificate verify failed (_ssl.c:777)]]
[07/07/2018 11:38] ERROR red <module> 634: Fatal exception, attempting graceful logout
Traceback (most recent call last):
  File "/Library/Frameworks/Python.framework/Versions/3.6/lib/python3.6/site-packages/aiohttp/connector.py", line 601, in _create_direct_connection
    local_addr=self._local_addr)
  File "/Library/Frameworks/Python.framework/Versions/3.6/lib/python3.6/asyncio/base_events.py", line 803, in create_connection
    sock, protocol_factory, ssl, server_hostname)
  File "/Library/Frameworks/Python.framework/Versions/3.6/lib/python3.6/asyncio/base_events.py", line 829, in _create_connection_transport
    yield from waiter
  File "/Library/Frameworks/Python.framework/Versions/3.6/lib/python3.6/asyncio/sslproto.py", line 501, in data_received
    ssldata, appdata = self._sslpipe.feed_ssldata(data)
  File "/Library/Frameworks/Python.framework/Versions/3.6/lib/python3.6/asyncio/sslproto.py", line 201, in feed_ssldata
    self._sslobj.do_handshake()
  File "/Library/Frameworks/Python.framework/Versions/3.6/lib/python3.6/ssl.py", line 689, in do_handshake
    self._sslobj.do_handshake()
ssl.SSLError: [SSL: CERTIFICATE_VERIFY_FAILED] certificate verify failed (_ssl.c:777)

The above exception was the direct cause of the following exception:

Traceback (most recent call last):
  File "/Library/Frameworks/Python.framework/Versions/3.6/lib/python3.6/site-packages/aiohttp/connector.py", line 304, in connect
    yield from self._create_connection(req)
  File "/Library/Frameworks/Python.framework/Versions/3.6/lib/python3.6/site-packages/aiohttp/connector.py", line 578, in _create_connection
    transport, proto = yield from self._create_direct_connection(req)
  File "/Library/Frameworks/Python.framework/Versions/3.6/lib/python3.6/site-packages/aiohttp/connector.py", line 624, in _create_direct_connection
    (req.host, req.port, exc.strerror)) from exc
aiohttp.errors.ClientOSError: [Errno 1] Can not connect to discordapp.com:443 [[SSL: CERTIFICATE_VERIFY_FAILED] certificate verify failed (_ssl.c:777)]

The above exception was the direct cause of the following exception:

Traceback (most recent call last):
  File "red.py", line 614, in <module>
    loop.run_until_complete(main(bot))
  File "/Library/Frameworks/Python.framework/Versions/3.6/lib/python3.6/asyncio/base_events.py", line 467, in run_until_complete
    return future.result()
  File "red.py", line 599, in main
    bot=not bot.settings.self_bot)
  File "/Library/Frameworks/Python.framework/Versions/3.6/lib/python3.6/site-packages/discord/client.py", line 416, in login
    yield from getattr(self, '_login_' + str(n))(*args, **kwargs)
  File "/Library/Frameworks/Python.framework/Versions/3.6/lib/python3.6/site-packages/discord/client.py", line 346, in _login_1
    data = yield from self.http.static_login(token, bot=is_bot)
  File "/Library/Frameworks/Python.framework/Versions/3.6/lib/python3.6/site-packages/discord/http.py", line 258, in static_login
    data = yield from self.request(Route('GET', '/users/@me'))
  File "/Library/Frameworks/Python.framework/Versions/3.6/lib/python3.6/site-packages/discord/http.py", line 137, in request
    r = yield from self.session.request(method, url, **kwargs)
  File "/Library/Frameworks/Python.framework/Versions/3.6/lib/python3.6/site-packages/aiohttp/client.py", line 555, in __iter__
    resp = yield from self._coro
  File "/Library/Frameworks/Python.framework/Versions/3.6/lib/python3.6/site-packages/aiohttp/client.py", line 198, in _request
    conn = yield from self._connector.connect(req)
  File "/Library/Frameworks/Python.framework/Versions/3.6/lib/python3.6/site-packages/aiohttp/connector.py", line 314, in connect
    .format(key, exc.strerror)) from exc
aiohttp.errors.ClientOSError: [Errno 1] Cannot connect to host discordapp.com:443 ssl:True [Can not connect to discordapp.com:443 [[SSL: CERTIFICATE_VERIFY_FAILED] certificate verify failed (_ssl.c:777)]]
[07/07/2018 11:38] ERROR red <module> 634: Fatal exception, attempting graceful logout
Traceback (most recent call last):
  File "/Library/Frameworks/Python.framework/Versions/3.6/lib/python3.6/site-packages/aiohttp/connector.py", line 601, in _create_direct_connection
    local_addr=self._local_addr)
  File "/Library/Frameworks/Python.framework/Versions/3.6/lib/python3.6/asyncio/base_events.py", line 803, in create_connection
    sock, protocol_factory, ssl, server_hostname)
  File "/Library/Frameworks/Python.framework/Versions/3.6/lib/python3.6/asyncio/base_events.py", line 829, in _create_connection_transport
    yield from waiter
  File "/Library/Frameworks/Python.framework/Versions/3.6/lib/python3.6/asyncio/sslproto.py", line 501, in data_received
    ssldata, appdata = self._sslpipe.feed_ssldata(data)
  File "/Library/Frameworks/Python.framework/Versions/3.6/lib/python3.6/asyncio/sslproto.py", line 201, in feed_ssldata
    self._sslobj.do_handshake()
  File "/Library/Frameworks/Python.framework/Versions/3.6/lib/python3.6/ssl.py", line 689, in do_handshake
    self._sslobj.do_handshake()
ssl.SSLError: [SSL: CERTIFICATE_VERIFY_FAILED] certificate verify failed (_ssl.c:777)

The above exception was the direct cause of the following exception:

Traceback (most recent call last):
  File "/Library/Frameworks/Python.framework/Versions/3.6/lib/python3.6/site-packages/aiohttp/connector.py", line 304, in connect
    yield from self._create_connection(req)
  File "/Library/Frameworks/Python.framework/Versions/3.6/lib/python3.6/site-packages/aiohttp/connector.py", line 578, in _create_connection
    transport, proto = yield from self._create_direct_connection(req)
  File "/Library/Frameworks/Python.framework/Versions/3.6/lib/python3.6/site-packages/aiohttp/connector.py", line 624, in _create_direct_connection
    (req.host, req.port, exc.strerror)) from exc
aiohttp.errors.ClientOSError: [Errno 1] Can not connect to discordapp.com:443 [[SSL: CERTIFICATE_VERIFY_FAILED] certificate verify failed (_ssl.c:777)]

The above exception was the direct cause of the following exception:

Traceback (most recent call last):
  File "red.py", line 614, in <module>
    loop.run_until_complete(main(bot))
  File "/Library/Frameworks/Python.framework/Versions/3.6/lib/python3.6/asyncio/base_events.py", line 467, in run_until_complete
    return future.result()
  File "red.py", line 599, in main
    bot=not bot.settings.self_bot)
  File "/Library/Frameworks/Python.framework/Versions/3.6/lib/python3.6/site-packages/discord/client.py", line 416, in login
    yield from getattr(self, '_login_' + str(n))(*args, **kwargs)
  File "/Library/Frameworks/Python.framework/Versions/3.6/lib/python3.6/site-packages/discord/client.py", line 346, in _login_1
    data = yield from self.http.static_login(token, bot=is_bot)
  File "/Library/Frameworks/Python.framework/Versions/3.6/lib/python3.6/site-packages/discord/http.py", line 258, in static_login
    data = yield from self.request(Route('GET', '/users/@me'))
  File "/Library/Frameworks/Python.framework/Versions/3.6/lib/python3.6/site-packages/discord/http.py", line 137, in request
    r = yield from self.session.request(method, url, **kwargs)
  File "/Library/Frameworks/Python.framework/Versions/3.6/lib/python3.6/site-packages/aiohttp/client.py", line 555, in __iter__
    resp = yield from self._coro
  File "/Library/Frameworks/Python.framework/Versions/3.6/lib/python3.6/site-packages/aiohttp/client.py", line 198, in _request
    conn = yield from self._connector.connect(req)
  File "/Library/Frameworks/Python.framework/Versions/3.6/lib/python3.6/site-packages/aiohttp/connector.py", line 314, in connect
    .format(key, exc.strerror)) from exc
aiohttp.errors.ClientOSError: [Errno 1] Cannot connect to host discordapp.com:443 ssl:True [Can not connect to discordapp.com:443 [[SSL: CERTIFICATE_VERIFY_FAILED] certificate verify failed (_ssl.c:777)]]
[07/07/2018 11:38] ERROR red <module> 634: Fatal exception, attempting graceful logout
Traceback (most recent call last):
  File "/Library/Frameworks/Python.framework/Versions/3.6/lib/python3.6/site-packages/aiohttp/connector.py", line 601, in _create_direct_connection
    local_addr=self._local_addr)
  File "/Library/Frameworks/Python.framework/Versions/3.6/lib/python3.6/asyncio/base_events.py", line 803, in create_connection
    sock, protocol_factory, ssl, server_hostname)
  File "/Library/Frameworks/Python.framework/Versions/3.6/lib/python3.6/asyncio/base_events.py", line 829, in _create_connection_transport
    yield from waiter
  File "/Library/Frameworks/Python.framework/Versions/3.6/lib/python3.6/asyncio/sslproto.py", line 501, in data_received
    ssldata, appdata = self._sslpipe.feed_ssldata(data)
  File "/Library/Frameworks/Python.framework/Versions/3.6/lib/python3.6/asyncio/sslproto.py", line 201, in feed_ssldata
    self._sslobj.do_handshake()
  File "/Library/Frameworks/Python.framework/Versions/3.6/lib/python3.6/ssl.py", line 689, in do_handshake
    self._sslobj.do_handshake()
ssl.SSLError: [SSL: CERTIFICATE_VERIFY_FAILED] certificate verify failed (_ssl.c:777)

The above exception was the direct cause of the following exception:

Traceback (most recent call last):
  File "/Library/Frameworks/Python.framework/Versions/3.6/lib/python3.6/site-packages/aiohttp/connector.py", line 304, in connect
    yield from self._create_connection(req)
  File "/Library/Frameworks/Python.framework/Versions/3.6/lib/python3.6/site-packages/aiohttp/connector.py", line 578, in _create_connection
    transport, proto = yield from self._create_direct_connection(req)
  File "/Library/Frameworks/Python.framework/Versions/3.6/lib/python3.6/site-packages/aiohttp/connector.py", line 624, in _create_direct_connection
    (req.host, req.port, exc.strerror)) from exc
aiohttp.errors.ClientOSError: [Errno 1] Can not connect to discordapp.com:443 [[SSL: CERTIFICATE_VERIFY_FAILED] certificate verify failed (_ssl.c:777)]

The above exception was the direct cause of the following exception:

Traceback (most recent call last):
  File "red.py", line 614, in <module>
    loop.run_until_complete(main(bot))
  File "/Library/Frameworks/Python.framework/Versions/3.6/lib/python3.6/asyncio/base_events.py", line 467, in run_until_complete
    return future.result()
  File "red.py", line 599, in main
    bot=not bot.settings.self_bot)
  File "/Library/Frameworks/Python.framework/Versions/3.6/lib/python3.6/site-packages/discord/client.py", line 416, in login
    yield from getattr(self, '_login_' + str(n))(*args, **kwargs)
  File "/Library/Frameworks/Python.framework/Versions/3.6/lib/python3.6/site-packages/discord/client.py", line 346, in _login_1
    data = yield from self.http.static_login(token, bot=is_bot)
  File "/Library/Frameworks/Python.framework/Versions/3.6/lib/python3.6/site-packages/discord/http.py", line 258, in static_login
    data = yield from self.request(Route('GET', '/users/@me'))
  File "/Library/Frameworks/Python.framework/Versions/3.6/lib/python3.6/site-packages/discord/http.py", line 137, in request
    r = yield from self.session.request(method, url, **kwargs)
  File "/Library/Frameworks/Python.framework/Versions/3.6/lib/python3.6/site-packages/aiohttp/client.py", line 555, in __iter__
    resp = yield from self._coro
  File "/Library/Frameworks/Python.framework/Versions/3.6/lib/python3.6/site-packages/aiohttp/client.py", line 198, in _request
    conn = yield from self._connector.connect(req)
  File "/Library/Frameworks/Python.framework/Versions/3.6/lib/python3.6/site-packages/aiohttp/connector.py", line 314, in connect
    .format(key, exc.strerror)) from exc
aiohttp.errors.ClientOSError: [Errno 1] Cannot connect to host discordapp.com:443 ssl:True [Can not connect to discordapp.com:443 [[SSL: CERTIFICATE_VERIFY_FAILED] certificate verify failed (_ssl.c:777)]]
[07/07/2018 11:38] ERROR red <module> 634: Fatal exception, attempting graceful logout
Traceback (most recent call last):
  File "/Library/Frameworks/Python.framework/Versions/3.6/lib/python3.6/site-packages/aiohttp/connector.py", line 601, in _create_direct_connection
    local_addr=self._local_addr)
  File "/Library/Frameworks/Python.framework/Versions/3.6/lib/python3.6/asyncio/base_events.py", line 803, in create_connection
    sock, protocol_factory, ssl, server_hostname)
  File "/Library/Frameworks/Python.framework/Versions/3.6/lib/python3.6/asyncio/base_events.py", line 829, in _create_connection_transport
    yield from waiter
  File "/Library/Frameworks/Python.framework/Versions/3.6/lib/python3.6/asyncio/sslproto.py", line 501, in data_received
    ssldata, appdata = self._sslpipe.feed_ssldata(data)
  File "/Library/Frameworks/Python.framework/Versions/3.6/lib/python3.6/asyncio/sslproto.py", line 201, in feed_ssldata
    self._sslobj.do_handshake()
  File "/Library/Frameworks/Python.framework/Versions/3.6/lib/python3.6/ssl.py", line 689, in do_handshake
    self._sslobj.do_handshake()
ssl.SSLError: [SSL: CERTIFICATE_VERIFY_FAILED] certificate verify failed (_ssl.c:777)

The above exception was the direct cause of the following exception:

Traceback (most recent call last):
  File "/Library/Frameworks/Python.framework/Versions/3.6/lib/python3.6/site-packages/aiohttp/connector.py", line 304, in connect
    yield from self._create_connection(req)
  File "/Library/Frameworks/Python.framework/Versions/3.6/lib/python3.6/site-packages/aiohttp/connector.py", line 578, in _create_connection
    transport, proto = yield from self._create_direct_connection(req)
  File "/Library/Frameworks/Python.framework/Versions/3.6/lib/python3.6/site-packages/aiohttp/connector.py", line 624, in _create_direct_connection
    (req.host, req.port, exc.strerror)) from exc
aiohttp.errors.ClientOSError: [Errno 1] Can not connect to discordapp.com:443 [[SSL: CERTIFICATE_VERIFY_FAILED] certificate verify failed (_ssl.c:777)]

The above exception was the direct cause of the following exception:

Traceback (most recent call last):
  File "red.py", line 614, in <module>
    loop.run_until_complete(main(bot))
  File "/Library/Frameworks/Python.framework/Versions/3.6/lib/python3.6/asyncio/base_events.py", line 467, in run_until_complete
    return future.result()
  File "red.py", line 599, in main
    bot=not bot.settings.self_bot)
  File "/Library/Frameworks/Python.framework/Versions/3.6/lib/python3.6/site-packages/discord/client.py", line 416, in login
    yield from getattr(self, '_login_' + str(n))(*args, **kwargs)
  File "/Library/Frameworks/Python.framework/Versions/3.6/lib/python3.6/site-packages/discord/client.py", line 346, in _login_1
    data = yield from self.http.static_login(token, bot=is_bot)
  File "/Library/Frameworks/Python.framework/Versions/3.6/lib/python3.6/site-packages/discord/http.py", line 258, in static_login
    data = yield from self.request(Route('GET', '/users/@me'))
  File "/Library/Frameworks/Python.framework/Versions/3.6/lib/python3.6/site-packages/discord/http.py", line 137, in request
    r = yield from self.session.request(method, url, **kwargs)
  File "/Library/Frameworks/Python.framework/Versions/3.6/lib/python3.6/site-packages/aiohttp/client.py", line 555, in __iter__
    resp = yield from self._coro
  File "/Library/Frameworks/Python.framework/Versions/3.6/lib/python3.6/site-packages/aiohttp/client.py", line 198, in _request
    conn = yield from self._connector.connect(req)
  File "/Library/Frameworks/Python.framework/Versions/3.6/lib/python3.6/site-packages/aiohttp/connector.py", line 314, in connect
    .format(key, exc.strerror)) from exc
aiohttp.errors.ClientOSError: [Errno 1] Cannot connect to host discordapp.com:443 ssl:True [Can not connect to discordapp.com:443 [[SSL: CERTIFICATE_VERIFY_FAILED] certificate verify failed (_ssl.c:777)]]
[07/07/2018 11:38] ERROR red <module> 634: Fatal exception, attempting graceful logout
Traceback (most recent call last):
  File "/Library/Frameworks/Python.framework/Versions/3.6/lib/python3.6/site-packages/aiohttp/connector.py", line 601, in _create_direct_connection
    local_addr=self._local_addr)
  File "/Library/Frameworks/Python.framework/Versions/3.6/lib/python3.6/asyncio/base_events.py", line 803, in create_connection
    sock, protocol_factory, ssl, server_hostname)
  File "/Library/Frameworks/Python.framework/Versions/3.6/lib/python3.6/asyncio/base_events.py", line 829, in _create_connection_transport
    yield from waiter
  File "/Library/Frameworks/Python.framework/Versions/3.6/lib/python3.6/asyncio/sslproto.py", line 501, in data_received
    ssldata, appdata = self._sslpipe.feed_ssldata(data)
  File "/Library/Frameworks/Python.framework/Versions/3.6/lib/python3.6/asyncio/sslproto.py", line 201, in feed_ssldata
    self._sslobj.do_handshake()
  File "/Library/Frameworks/Python.framework/Versions/3.6/lib/python3.6/ssl.py", line 689, in do_handshake
    self._sslobj.do_handshake()
ssl.SSLError: [SSL: CERTIFICATE_VERIFY_FAILED] certificate verify failed (_ssl.c:777)

The above exception was the direct cause of the following exception:

Traceback (most recent call last):
  File "/Library/Frameworks/Python.framework/Versions/3.6/lib/python3.6/site-packages/aiohttp/connector.py", line 304, in connect
    yield from self._create_connection(req)
  File "/Library/Frameworks/Python.framework/Versions/3.6/lib/python3.6/site-packages/aiohttp/connector.py", line 578, in _create_connection
    transport, proto = yield from self._create_direct_connection(req)
  File "/Library/Frameworks/Python.framework/Versions/3.6/lib/python3.6/site-packages/aiohttp/connector.py", line 624, in _create_direct_connection
    (req.host, req.port, exc.strerror)) from exc
aiohttp.errors.ClientOSError: [Errno 1] Can not connect to discordapp.com:443 [[SSL: CERTIFICATE_VERIFY_FAILED] certificate verify failed (_ssl.c:777)]

The above exception was the direct cause of the following exception:

Traceback (most recent call last):
  File "red.py", line 614, in <module>
    loop.run_until_complete(main(bot))
  File "/Library/Frameworks/Python.framework/Versions/3.6/lib/python3.6/asyncio/base_events.py", line 467, in run_until_complete
    return future.result()
  File "red.py", line 599, in main
    bot=not bot.settings.self_bot)
  File "/Library/Frameworks/Python.framework/Versions/3.6/lib/python3.6/site-packages/discord/client.py", line 416, in login
    yield from getattr(self, '_login_' + str(n))(*args, **kwargs)
  File "/Library/Frameworks/Python.framework/Versions/3.6/lib/python3.6/site-packages/discord/client.py", line 346, in _login_1
    data = yield from self.http.static_login(token, bot=is_bot)
  File "/Library/Frameworks/Python.framework/Versions/3.6/lib/python3.6/site-packages/discord/http.py", line 258, in static_login
    data = yield from self.request(Route('GET', '/users/@me'))
  File "/Library/Frameworks/Python.framework/Versions/3.6/lib/python3.6/site-packages/discord/http.py", line 137, in request
    r = yield from self.session.request(method, url, **kwargs)
  File "/Library/Frameworks/Python.framework/Versions/3.6/lib/python3.6/site-packages/aiohttp/client.py", line 555, in __iter__
    resp = yield from self._coro
  File "/Library/Frameworks/Python.framework/Versions/3.6/lib/python3.6/site-packages/aiohttp/client.py", line 198, in _request
    conn = yield from self._connector.connect(req)
  File "/Library/Frameworks/Python.framework/Versions/3.6/lib/python3.6/site-packages/aiohttp/connector.py", line 314, in connect
    .format(key, exc.strerror)) from exc
aiohttp.errors.ClientOSError: [Errno 1] Cannot connect to host discordapp.com:443 ssl:True [Can not connect to discordapp.com:443 [[SSL: CERTIFICATE_VERIFY_FAILED] certificate verify failed (_ssl.c:777)]]
[07/07/2018 11:38] ERROR red <module> 634: Fatal exception, attempting graceful logout
Traceback (most recent call last):
  File "/Library/Frameworks/Python.framework/Versions/3.6/lib/python3.6/site-packages/aiohttp/connector.py", line 601, in _create_direct_connection
    local_addr=self._local_addr)
  File "/Library/Frameworks/Python.framework/Versions/3.6/lib/python3.6/asyncio/base_events.py", line 803, in create_connection
    sock, protocol_factory, ssl, server_hostname)
  File "/Library/Frameworks/Python.framework/Versions/3.6/lib/python3.6/asyncio/base_events.py", line 829, in _create_connection_transport
    yield from waiter
  File "/Library/Frameworks/Python.framework/Versions/3.6/lib/python3.6/asyncio/sslproto.py", line 501, in data_received
    ssldata, appdata = self._sslpipe.feed_ssldata(data)
  File "/Library/Frameworks/Python.framework/Versions/3.6/lib/python3.6/asyncio/sslproto.py", line 201, in feed_ssldata
    self._sslobj.do_handshake()
  File "/Library/Frameworks/Python.framework/Versions/3.6/lib/python3.6/ssl.py", line 689, in do_handshake
    self._sslobj.do_handshake()
ssl.SSLError: [SSL: CERTIFICATE_VERIFY_FAILED] certificate verify failed (_ssl.c:777)

The above exception was the direct cause of the following exception:

Traceback (most recent call last):
  File "/Library/Frameworks/Python.framework/Versions/3.6/lib/python3.6/site-packages/aiohttp/connector.py", line 304, in connect
    yield from self._create_connection(req)
  File "/Library/Frameworks/Python.framework/Versions/3.6/lib/python3.6/site-packages/aiohttp/connector.py", line 578, in _create_connection
    transport, proto = yield from self._create_direct_connection(req)
  File "/Library/Frameworks/Python.framework/Versions/3.6/lib/python3.6/site-packages/aiohttp/connector.py", line 624, in _create_direct_connection
    (req.host, req.port, exc.strerror)) from exc
aiohttp.errors.ClientOSError: [Errno 1] Can not connect to discordapp.com:443 [[SSL: CERTIFICATE_VERIFY_FAILED] certificate verify failed (_ssl.c:777)]

The above exception was the direct cause of the following exception:

Traceback (most recent call last):
  File "red.py", line 614, in <module>
    loop.run_until_complete(main(bot))
  File "/Library/Frameworks/Python.framework/Versions/3.6/lib/python3.6/asyncio/base_events.py", line 467, in run_until_complete
    return future.result()
  File "red.py", line 599, in main
    bot=not bot.settings.self_bot)
  File "/Library/Frameworks/Python.framework/Versions/3.6/lib/python3.6/site-packages/discord/client.py", line 416, in login
    yield from getattr(self, '_login_' + str(n))(*args, **kwargs)
  File "/Library/Frameworks/Python.framework/Versions/3.6/lib/python3.6/site-packages/discord/client.py", line 346, in _login_1
    data = yield from self.http.static_login(token, bot=is_bot)
  File "/Library/Frameworks/Python.framework/Versions/3.6/lib/python3.6/site-packages/discord/http.py", line 258, in static_login
    data = yield from self.request(Route('GET', '/users/@me'))
  File "/Library/Frameworks/Python.framework/Versions/3.6/lib/python3.6/site-packages/discord/http.py", line 137, in request
    r = yield from self.session.request(method, url, **kwargs)
  File "/Library/Frameworks/Python.framework/Versions/3.6/lib/python3.6/site-packages/aiohttp/client.py", line 555, in __iter__
    resp = yield from self._coro
  File "/Library/Frameworks/Python.framework/Versions/3.6/lib/python3.6/site-packages/aiohttp/client.py", line 198, in _request
    conn = yield from self._connector.connect(req)
  File "/Library/Frameworks/Python.framework/Versions/3.6/lib/python3.6/site-packages/aiohttp/connector.py", line 314, in connect
    .format(key, exc.strerror)) from exc
aiohttp.errors.ClientOSError: [Errno 1] Cannot connect to host discordapp.com:443 ssl:True [Can not connect to discordapp.com:443 [[SSL: CERTIFICATE_VERIFY_FAILED] certificate verify failed (_ssl.c:777)]]
[07/07/2018 11:38] ERROR red <module> 634: Fatal exception, attempting graceful logout
Traceback (most recent call last):
  File "/Library/Frameworks/Python.framework/Versions/3.6/lib/python3.6/site-packages/aiohttp/connector.py", line 601, in _create_direct_connection
    local_addr=self._local_addr)
  File "/Library/Frameworks/Python.framework/Versions/3.6/lib/python3.6/asyncio/base_events.py", line 803, in create_connection
    sock, protocol_factory, ssl, server_hostname)
  File "/Library/Frameworks/Python.framework/Versions/3.6/lib/python3.6/asyncio/base_events.py", line 829, in _create_connection_transport
    yield from waiter
  File "/Library/Frameworks/Python.framework/Versions/3.6/lib/python3.6/asyncio/sslproto.py", line 501, in data_received
    ssldata, appdata = self._sslpipe.feed_ssldata(data)
  File "/Library/Frameworks/Python.framework/Versions/3.6/lib/python3.6/asyncio/sslproto.py", line 201, in feed_ssldata
    self._sslobj.do_handshake()
  File "/Library/Frameworks/Python.framework/Versions/3.6/lib/python3.6/ssl.py", line 689, in do_handshake
    self._sslobj.do_handshake()
ssl.SSLError: [SSL: CERTIFICATE_VERIFY_FAILED] certificate verify failed (_ssl.c:777)

The above exception was the direct cause of the following exception:

Traceback (most recent call last):
  File "/Library/Frameworks/Python.framework/Versions/3.6/lib/python3.6/site-packages/aiohttp/connector.py", line 304, in connect
    yield from self._create_connection(req)
  File "/Library/Frameworks/Python.framework/Versions/3.6/lib/python3.6/site-packages/aiohttp/connector.py", line 578, in _create_connection
    transport, proto = yield from self._create_direct_connection(req)
  File "/Library/Frameworks/Python.framework/Versions/3.6/lib/python3.6/site-packages/aiohttp/connector.py", line 624, in _create_direct_connection
    (req.host, req.port, exc.strerror)) from exc
aiohttp.errors.ClientOSError: [Errno 1] Can not connect to discordapp.com:443 [[SSL: CERTIFICATE_VERIFY_FAILED] certificate verify failed (_ssl.c:777)]

The above exception was the direct cause of the following exception:

Traceback (most recent call last):
  File "red.py", line 614, in <module>
    loop.run_until_complete(main(bot))
  File "/Library/Frameworks/Python.framework/Versions/3.6/lib/python3.6/asyncio/base_events.py", line 467, in run_until_complete
    return future.result()
  File "red.py", line 599, in main
    bot=not bot.settings.self_bot)
  File "/Library/Frameworks/Python.framework/Versions/3.6/lib/python3.6/site-packages/discord/client.py", line 416, in login
    yield from getattr(self, '_login_' + str(n))(*args, **kwargs)
  File "/Library/Frameworks/Python.framework/Versions/3.6/lib/python3.6/site-packages/discord/client.py", line 346, in _login_1
    data = yield from self.http.static_login(token, bot=is_bot)
  File "/Library/Frameworks/Python.framework/Versions/3.6/lib/python3.6/site-packages/discord/http.py", line 258, in static_login
    data = yield from self.request(Route('GET', '/users/@me'))
  File "/Library/Frameworks/Python.framework/Versions/3.6/lib/python3.6/site-packages/discord/http.py", line 137, in request
    r = yield from self.session.request(method, url, **kwargs)
  File "/Library/Frameworks/Python.framework/Versions/3.6/lib/python3.6/site-packages/aiohttp/client.py", line 555, in __iter__
    resp = yield from self._coro
  File "/Library/Frameworks/Python.framework/Versions/3.6/lib/python3.6/site-packages/aiohttp/client.py", line 198, in _request
    conn = yield from self._connector.connect(req)
  File "/Library/Frameworks/Python.framework/Versions/3.6/lib/python3.6/site-packages/aiohttp/connector.py", line 314, in connect
    .format(key, exc.strerror)) from exc
aiohttp.errors.ClientOSError: [Errno 1] Cannot connect to host discordapp.com:443 ssl:True [Can not connect to discordapp.com:443 [[SSL: CERTIFICATE_VERIFY_FAILED] certificate verify failed (_ssl.c:777)]]
[07/07/2018 11:38] ERROR red <module> 634: Fatal exception, attempting graceful logout
Traceback (most recent call last):
  File "/Library/Frameworks/Python.framework/Versions/3.6/lib/python3.6/site-packages/aiohttp/connector.py", line 601, in _create_direct_connection
    local_addr=self._local_addr)
  File "/Library/Frameworks/Python.framework/Versions/3.6/lib/python3.6/asyncio/base_events.py", line 803, in create_connection
    sock, protocol_factory, ssl, server_hostname)
  File "/Library/Frameworks/Python.framework/Versions/3.6/lib/python3.6/asyncio/base_events.py", line 829, in _create_connection_transport
    yield from waiter
  File "/Library/Frameworks/Python.framework/Versions/3.6/lib/python3.6/asyncio/sslproto.py", line 501, in data_received
    ssldata, appdata = self._sslpipe.feed_ssldata(data)
  File "/Library/Frameworks/Python.framework/Versions/3.6/lib/python3.6/asyncio/sslproto.py", line 201, in feed_ssldata
    self._sslobj.do_handshake()
  File "/Library/Frameworks/Python.framework/Versions/3.6/lib/python3.6/ssl.py", line 689, in do_handshake
    self._sslobj.do_handshake()
ssl.SSLError: [SSL: CERTIFICATE_VERIFY_FAILED] certificate verify failed (_ssl.c:777)

The above exception was the direct cause of the following exception:

Traceback (most recent call last):
  File "/Library/Frameworks/Python.framework/Versions/3.6/lib/python3.6/site-packages/aiohttp/connector.py", line 304, in connect
    yield from self._create_connection(req)
  File "/Library/Frameworks/Python.framework/Versions/3.6/lib/python3.6/site-packages/aiohttp/connector.py", line 578, in _create_connection
    transport, proto = yield from self._create_direct_connection(req)
  File "/Library/Frameworks/Python.framework/Versions/3.6/lib/python3.6/site-packages/aiohttp/connector.py", line 624, in _create_direct_connection
    (req.host, req.port, exc.strerror)) from exc
aiohttp.errors.ClientOSError: [Errno 1] Can not connect to discordapp.com:443 [[SSL: CERTIFICATE_VERIFY_FAILED] certificate verify failed (_ssl.c:777)]

The above exception was the direct cause of the following exception:

Traceback (most recent call last):
  File "red.py", line 614, in <module>
    loop.run_until_complete(main(bot))
  File "/Library/Frameworks/Python.framework/Versions/3.6/lib/python3.6/asyncio/base_events.py", line 467, in run_until_complete
    return future.result()
  File "red.py", line 599, in main
    bot=not bot.settings.self_bot)
  File "/Library/Frameworks/Python.framework/Versions/3.6/lib/python3.6/site-packages/discord/client.py", line 416, in login
    yield from getattr(self, '_login_' + str(n))(*args, **kwargs)
  File "/Library/Frameworks/Python.framework/Versions/3.6/lib/python3.6/site-packages/discord/client.py", line 346, in _login_1
    data = yield from self.http.static_login(token, bot=is_bot)
  File "/Library/Frameworks/Python.framework/Versions/3.6/lib/python3.6/site-packages/discord/http.py", line 258, in static_login
    data = yield from self.request(Route('GET', '/users/@me'))
  File "/Library/Frameworks/Python.framework/Versions/3.6/lib/python3.6/site-packages/discord/http.py", line 137, in request
    r = yield from self.session.request(method, url, **kwargs)
  File "/Library/Frameworks/Python.framework/Versions/3.6/lib/python3.6/site-packages/aiohttp/client.py", line 555, in __iter__
    resp = yield from self._coro
  File "/Library/Frameworks/Python.framework/Versions/3.6/lib/python3.6/site-packages/aiohttp/client.py", line 198, in _request
    conn = yield from self._connector.connect(req)
  File "/Library/Frameworks/Python.framework/Versions/3.6/lib/python3.6/site-packages/aiohttp/connector.py", line 314, in connect
    .format(key, exc.strerror)) from exc
aiohttp.errors.ClientOSError: [Errno 1] Cannot connect to host discordapp.com:443 ssl:True [Can not connect to discordapp.com:443 [[SSL: CERTIFICATE_VERIFY_FAILED] certificate verify failed (_ssl.c:777)]]
[07/07/2018 11:40] ERROR red <module> 634: Fatal exception, attempting graceful logout
Traceback (most recent call last):
  File "/Library/Frameworks/Python.framework/Versions/3.6/lib/python3.6/site-packages/aiohttp/connector.py", line 601, in _create_direct_connection
    local_addr=self._local_addr)
  File "/Library/Frameworks/Python.framework/Versions/3.6/lib/python3.6/asyncio/base_events.py", line 803, in create_connection
    sock, protocol_factory, ssl, server_hostname)
  File "/Library/Frameworks/Python.framework/Versions/3.6/lib/python3.6/asyncio/base_events.py", line 829, in _create_connection_transport
    yield from waiter
  File "/Library/Frameworks/Python.framework/Versions/3.6/lib/python3.6/asyncio/sslproto.py", line 501, in data_received
    ssldata, appdata = self._sslpipe.feed_ssldata(data)
  File "/Library/Frameworks/Python.framework/Versions/3.6/lib/python3.6/asyncio/sslproto.py", line 201, in feed_ssldata
    self._sslobj.do_handshake()
  File "/Library/Frameworks/Python.framework/Versions/3.6/lib/python3.6/ssl.py", line 689, in do_handshake
    self._sslobj.do_handshake()
ssl.SSLError: [SSL: CERTIFICATE_VERIFY_FAILED] certificate verify failed (_ssl.c:777)

The above exception was the direct cause of the following exception:

Traceback (most recent call last):
  File "/Library/Frameworks/Python.framework/Versions/3.6/lib/python3.6/site-packages/aiohttp/connector.py", line 304, in connect
    yield from self._create_connection(req)
  File "/Library/Frameworks/Python.framework/Versions/3.6/lib/python3.6/site-packages/aiohttp/connector.py", line 578, in _create_connection
    transport, proto = yield from self._create_direct_connection(req)
  File "/Library/Frameworks/Python.framework/Versions/3.6/lib/python3.6/site-packages/aiohttp/connector.py", line 624, in _create_direct_connection
    (req.host, req.port, exc.strerror)) from exc
aiohttp.errors.ClientOSError: [Errno 1] Can not connect to discordapp.com:443 [[SSL: CERTIFICATE_VERIFY_FAILED] certificate verify failed (_ssl.c:777)]

The above exception was the direct cause of the following exception:

Traceback (most recent call last):
  File "red.py", line 614, in <module>
    loop.run_until_complete(main(bot))
  File "/Library/Frameworks/Python.framework/Versions/3.6/lib/python3.6/asyncio/base_events.py", line 467, in run_until_complete
    return future.result()
  File "red.py", line 599, in main
    bot=not bot.settings.self_bot)
  File "/Library/Frameworks/Python.framework/Versions/3.6/lib/python3.6/site-packages/discord/client.py", line 416, in login
    yield from getattr(self, '_login_' + str(n))(*args, **kwargs)
  File "/Library/Frameworks/Python.framework/Versions/3.6/lib/python3.6/site-packages/discord/client.py", line 346, in _login_1
    data = yield from self.http.static_login(token, bot=is_bot)
  File "/Library/Frameworks/Python.framework/Versions/3.6/lib/python3.6/site-packages/discord/http.py", line 258, in static_login
    data = yield from self.request(Route('GET', '/users/@me'))
  File "/Library/Frameworks/Python.framework/Versions/3.6/lib/python3.6/site-packages/discord/http.py", line 137, in request
    r = yield from self.session.request(method, url, **kwargs)
  File "/Library/Frameworks/Python.framework/Versions/3.6/lib/python3.6/site-packages/aiohttp/client.py", line 555, in __iter__
    resp = yield from self._coro
  File "/Library/Frameworks/Python.framework/Versions/3.6/lib/python3.6/site-packages/aiohttp/client.py", line 198, in _request
    conn = yield from self._connector.connect(req)
  File "/Library/Frameworks/Python.framework/Versions/3.6/lib/python3.6/site-packages/aiohttp/connector.py", line 314, in connect
    .format(key, exc.strerror)) from exc
aiohttp.errors.ClientOSError: [Errno 1] Cannot connect to host discordapp.com:443 ssl:True [Can not connect to discordapp.com:443 [[SSL: CERTIFICATE_VERIFY_FAILED] certificate verify failed (_ssl.c:777)]]
[07/07/2018 12:08] INFO economy _set 393: Finesse(300846304379142145) set 100 credits to lame boy kris (370774518995877898)
[07/07/2018 12:09] INFO economy transfer 352: lame boy kris(370774518995877898) transferred 1 credits to Finesse(300846304379142145)
[07/07/2018 12:09] INFO economy _set 393: Finesse(300846304379142145) set 100 credits to ShadowFox (198918477795426305)
[07/07/2018 12:17] INFO economy _set 393: Finesse(300846304379142145) set 100 credits to heatblast (265240029645897728)
[07/07/2018 19:37] WARNING sentry __init__ 32: Sentry: DSN key is not set. Not sending logs!
